Traceback (most recent call last):
  File "/home/codespace/.cache/pypoetry/virtualenvs/plenty-in-the-pantry-xPFdo8rA-py3.10/lib/python3.10/site-packages/jupyter_cache/executors/utils.py", line 58, in single_nb_execution
    executenb(
  File "/home/codespace/.cache/pypoetry/virtualenvs/plenty-in-the-pantry-xPFdo8rA-py3.10/lib/python3.10/site-packages/nbclient/client.py", line 1305, in execute
    return NotebookClient(nb=nb, resources=resources, km=km, **kwargs).execute()
  File "/home/codespace/.cache/pypoetry/virtualenvs/plenty-in-the-pantry-xPFdo8rA-py3.10/lib/python3.10/site-packages/jupyter_core/utils/__init__.py", line 165, in wrapped
    return loop.run_until_complete(inner)
  File "/usr/local/python/3.10.13/lib/python3.10/asyncio/base_events.py", line 649, in run_until_complete
    return future.result()
  File "/home/codespace/.cache/pypoetry/virtualenvs/plenty-in-the-pantry-xPFdo8rA-py3.10/lib/python3.10/site-packages/nbclient/client.py", line 705, in async_execute
    await self.async_execute_cell(
  File "/home/codespace/.cache/pypoetry/virtualenvs/plenty-in-the-pantry-xPFdo8rA-py3.10/lib/python3.10/site-packages/nbclient/client.py", line 1058, in async_execute_cell
    await self._check_raise_for_error(cell, cell_index, exec_reply)
  File "/home/codespace/.cache/pypoetry/virtualenvs/plenty-in-the-pantry-xPFdo8rA-py3.10/lib/python3.10/site-packages/nbclient/client.py", line 914, in _check_raise_for_error
    raise CellExecutionError.from_cell_and_msg(cell, exec_reply_content)
nbclient.exceptions.CellExecutionError: An error occurred while executing the following cell:
------------------
  # data for dow
# df_period1 = pd.read_csv (r"C:\Users\20204113\OneDrive - TU Eindhoven\2_Research\1_Groceries\DATA\9th week - narrative (3rd attempt)\HH2\df\df_HH2_period1.csv")
# df_period2 = pd.read_csv (r"C:\Users\20204113\OneDrive - TU Eindhoven\2_Research\1_Groceries\DATA\9th week - narrative (3rd attempt)\HH2\df\df_HH2_period2.csv")
from DAYS_HH2weights import period1, period2

  #Function to define the limits for total visits, days, same store and type per week
from AlgorithmCOUNTS_HH2 import CountTotalVisits, CountTotalDays, CountStoreName, CountTimePerDay, CountStoreType, CountTotalPerday, CountVisitsPerDay, CountTimingPerDay
------------------


[0;31m---------------------------------------------------------------------------[0m
[0;31mModuleNotFoundError[0m                       Traceback (most recent call last)
Cell [0;32mIn[2], line 4[0m
[1;32m      1[0m [38;5;66;03m# data for dow[39;00m
[1;32m      2[0m [38;5;66;03m# df_period1 = pd.read_csv (r"C:\Users\20204113\OneDrive - TU Eindhoven\2_Research\1_Groceries\DATA\9th week - narrative (3rd attempt)\HH2\df\df_HH2_period1.csv")[39;00m
[1;32m      3[0m [38;5;66;03m# df_period2 = pd.read_csv (r"C:\Users\20204113\OneDrive - TU Eindhoven\2_Research\1_Groceries\DATA\9th week - narrative (3rd attempt)\HH2\df\df_HH2_period2.csv")[39;00m
[0;32m----> 4[0m [38;5;28;01mfrom[39;00m [38;5;21;01mDAYS_HH2weights[39;00m [38;5;28;01mimport[39;00m period1, period2
[1;32m      6[0m [38;5;66;03m#Function to define the limits for total visits, days, same store and type per week[39;00m
[1;32m      7[0m [38;5;28;01mfrom[39;00m [38;5;21;01mAlgorithmCOUNTS_HH2[39;00m [38;5;28;01mimport[39;00m CountTotalVisits, CountTotalDays, CountStoreName, CountTimePerDay, CountStoreType, CountTotalPerday, CountVisitsPerDay, CountTimingPerDay

[0;31mModuleNotFoundError[0m: No module named 'DAYS_HH2weights'

