Traceback (most recent call last):
  File "/home/codespace/.cache/pypoetry/virtualenvs/plenty-in-the-pantry-xPFdo8rA-py3.10/lib/python3.10/site-packages/jupyter_cache/executors/utils.py", line 58, in single_nb_execution
    executenb(
  File "/home/codespace/.cache/pypoetry/virtualenvs/plenty-in-the-pantry-xPFdo8rA-py3.10/lib/python3.10/site-packages/nbclient/client.py", line 1305, in execute
    return NotebookClient(nb=nb, resources=resources, km=km, **kwargs).execute()
  File "/home/codespace/.cache/pypoetry/virtualenvs/plenty-in-the-pantry-xPFdo8rA-py3.10/lib/python3.10/site-packages/jupyter_core/utils/__init__.py", line 165, in wrapped
    return loop.run_until_complete(inner)
  File "/usr/local/python/3.10.13/lib/python3.10/asyncio/base_events.py", line 649, in run_until_complete
    return future.result()
  File "/home/codespace/.cache/pypoetry/virtualenvs/plenty-in-the-pantry-xPFdo8rA-py3.10/lib/python3.10/site-packages/nbclient/client.py", line 705, in async_execute
    await self.async_execute_cell(
  File "/home/codespace/.cache/pypoetry/virtualenvs/plenty-in-the-pantry-xPFdo8rA-py3.10/lib/python3.10/site-packages/nbclient/client.py", line 1058, in async_execute_cell
    await self._check_raise_for_error(cell, cell_index, exec_reply)
  File "/home/codespace/.cache/pypoetry/virtualenvs/plenty-in-the-pantry-xPFdo8rA-py3.10/lib/python3.10/site-packages/nbclient/client.py", line 914, in _check_raise_for_error
    raise CellExecutionError.from_cell_and_msg(cell, exec_reply_content)
nbclient.exceptions.CellExecutionError: An error occurred while executing the following cell:
------------------
df = pd.read_csv (r"C:\Users\20204113\OneDrive - TU Eindhoven\2_Research\1_Groceries\DATA\9th week - narrative (3rd attempt)\HH2\df\df_HH2.csv")
------------------


[0;31m---------------------------------------------------------------------------[0m
[0;31mNameError[0m                                 Traceback (most recent call last)
Cell [0;32mIn[1], line 1[0m
[0;32m----> 1[0m df [38;5;241m=[39m [43mpd[49m[38;5;241m.[39mread_csv ([38;5;124mr[39m[38;5;124m"[39m[38;5;124mC:[39m[38;5;124m\[39m[38;5;124mUsers[39m[38;5;124m\[39m[38;5;124m20204113[39m[38;5;124m\[39m[38;5;124mOneDrive - TU Eindhoven[39m[38;5;124m\[39m[38;5;124m2_Research[39m[38;5;124m\[39m[38;5;124m1_Groceries[39m[38;5;124m\[39m[38;5;124mDATA[39m[38;5;124m\[39m[38;5;124m9th week - narrative (3rd attempt)[39m[38;5;124m\[39m[38;5;124mHH2[39m[38;5;124m\[39m[38;5;124mdf[39m[38;5;124m\[39m[38;5;124mdf_HH2.csv[39m[38;5;124m"[39m)

[0;31mNameError[0m: name 'pd' is not defined

