Traceback (most recent call last):
  File "/home/codespace/.cache/pypoetry/virtualenvs/plenty-in-the-pantry-xPFdo8rA-py3.10/lib/python3.10/site-packages/jupyter_cache/executors/utils.py", line 58, in single_nb_execution
    executenb(
  File "/home/codespace/.cache/pypoetry/virtualenvs/plenty-in-the-pantry-xPFdo8rA-py3.10/lib/python3.10/site-packages/nbclient/client.py", line 1305, in execute
    return NotebookClient(nb=nb, resources=resources, km=km, **kwargs).execute()
  File "/home/codespace/.cache/pypoetry/virtualenvs/plenty-in-the-pantry-xPFdo8rA-py3.10/lib/python3.10/site-packages/jupyter_core/utils/__init__.py", line 165, in wrapped
    return loop.run_until_complete(inner)
  File "/usr/local/python/3.10.13/lib/python3.10/asyncio/base_events.py", line 649, in run_until_complete
    return future.result()
  File "/home/codespace/.cache/pypoetry/virtualenvs/plenty-in-the-pantry-xPFdo8rA-py3.10/lib/python3.10/site-packages/nbclient/client.py", line 705, in async_execute
    await self.async_execute_cell(
  File "/home/codespace/.cache/pypoetry/virtualenvs/plenty-in-the-pantry-xPFdo8rA-py3.10/lib/python3.10/site-packages/nbclient/client.py", line 1058, in async_execute_cell
    await self._check_raise_for_error(cell, cell_index, exec_reply)
  File "/home/codespace/.cache/pypoetry/virtualenvs/plenty-in-the-pantry-xPFdo8rA-py3.10/lib/python3.10/site-packages/nbclient/client.py", line 914, in _check_raise_for_error
    raise CellExecutionError.from_cell_and_msg(cell, exec_reply_content)
nbclient.exceptions.CellExecutionError: An error occurred while executing the following cell:
------------------
df_des = df.describe(include='all', datetime_is_numeric=True)

df_styled = df_des.style.background_gradient() #adding a gradient based on values in cell
dfi.export(df_styled,"describe.png")
------------------


[0;31m---------------------------------------------------------------------------[0m
[0;31mTypeError[0m                                 Traceback (most recent call last)
Cell [0;32mIn[7], line 1[0m
[0;32m----> 1[0m df_des [38;5;241m=[39m [43mdf[49m[38;5;241;43m.[39;49m[43mdescribe[49m[43m([49m[43minclude[49m[38;5;241;43m=[39;49m[38;5;124;43m'[39;49m[38;5;124;43mall[39;49m[38;5;124;43m'[39;49m[43m,[49m[43m [49m[43mdatetime_is_numeric[49m[38;5;241;43m=[39;49m[38;5;28;43;01mTrue[39;49;00m[43m)[49m
[1;32m      3[0m df_styled [38;5;241m=[39m df_des[38;5;241m.[39mstyle[38;5;241m.[39mbackground_gradient() [38;5;66;03m#adding a gradient based on values in cell[39;00m
[1;32m      4[0m dfi[38;5;241m.[39mexport(df_styled,[38;5;124m"[39m[38;5;124mdescribe.png[39m[38;5;124m"[39m)

[0;31mTypeError[0m: NDFrame.describe() got an unexpected keyword argument 'datetime_is_numeric'

